Workbook
Name Slicer_CustomerRegion: #N/A
Name Slicer_MonthName: #N/A
Name Slicer_ProductCategory: #N/A
Name Slicer_Salesperson: #N/A

Sheet Project Hub
X1: Last Updated: | AA1: =TODAY() -> 46134

Sheet Executive Dashboard
I1: =TODAY() -> 46134
B2: Sales & Inventory Intelligence Dashboard
B4: Excel Data Model | Power Pivot | Interactive Analysis

Sheet Inventory Dashboard
I1: =TODAY() -> 46134
B2: Inventory Risk & Stock Control Dashboard
B4: Current Stock | Movement Analysis | Reorder Risk
B7: =KPISheet!B10 -> Current Stock Value | D7: =KPISheet!B16 -> Current Stock Qty | F7: =KPISheet!B17 -> Stock In Qty | I7: =KPISheet!B18 -> Stock Out Qty | K7: =KPISheet!B11 -> Low Stock Products | M7: =KPISheet!B12 -> Out of Stock Products
B9: =GETPIVOTDATA("[Measures].[Current Stock Value]",KPISheet!$B$3) -> 223953.51 | D9: =GETPIVOTDATA("[Measures].[Current Stock Qty]",KPISheet!$B$3) -> 113418 | F9: =GETPIVOTDATA("[Measures].[Stock In Qty]",KPISheet!$B$3) -> 131303 | I9: =GETPIVOTDATA("[Measures].[Stock Out Qty]",KPISheet!$B$3) -> 17885 | K9: =GETPIVOTDATA("[Measures].[Low Stock Products]",KPISheet!$B$3) -> 1 | M9: =GETPIVOTDATA("[Measures].[Out of Stock Products]",KPISheet!$B$3) -> 1
B29: Category | C29: Product | E29: Reorder Level | F29: Current Stock | G29: Variance | H29: Stock Value | J29: Status
B30: {=IFERROR(INDEX(tblRiskInventory[ProductCategory],ROWS($B$29:B29)),"")} -> Canned | C30: {=IFERROR(INDEX(tblRiskInventory[ProductName],ROWS($C$29:C29)),"")} -> Chickpeas 500g | E30: {=IFERROR(INDEX(tblRiskInventory[ReorderLevel],ROWS($E$29:E29)),"")} -> 38 | F30: {=IFERROR(INDEX(tblRiskInventory[CurrentStockQty],ROWS($F$29:F29)),"")} -> -53 | G30: {=IFERROR(INDEX(tblRiskInventory[VarianceVsReorder],ROWS($G$29:G29)),"")} -> -91 | I30: {=IFERROR(INDEX(tblRiskInventory[CurrentStockValue],ROWS($I$29:I29)),"")} -> -126.14 | J30: {=IFERROR(INDEX(tblRiskInventory[Status],ROWS($J$29:J29)),"")} -> Out of Stock
B31: {=IFERROR(INDEX(tblRiskInventory[ProductCategory],ROWS($B$29:B30)),"")} -> Frozen | C31: {=IFERROR(INDEX(tblRiskInventory[ProductName],ROWS($C$29:C30)),"")} -> Frozen Pizza 350g | E31: {=IFERROR(INDEX(tblRiskInventory[ReorderLevel],ROWS($E$29:E30)),"")} -> 27 | F31: {=IFERROR(INDEX(tblRiskInventory[CurrentStockQty],ROWS($F$29:F30)),"")} -> 27 | G31: {=IFERROR(INDEX(tblRiskInventory[VarianceVsReorder],ROWS($G$29:G30)),"")} -> 0 | I31: {=IFERROR(INDEX(tblRiskInventory[CurrentStockValue],ROWS($I$29:I30)),"")} -> 121.5 | J31: {=IFERROR(INDEX(tblRiskInventory[Status],ROWS($J$29:J30)),"")} -> Low Stock

Sheet Profitability Dashboard
P1: =TODAY() -> 46134
B2: Profitability & Discount Analysis Dashboard
B4: Margin | Discount Impact | Profit Drivers
S12: Category | T12: Gross profit | U12: Gross Margin %
S13: =Pivot_Source!L16 -> Beverages | T13: =Pivot_Source!M16 -> 13216.738 | U13: =Pivot_Source!N16 -> 0.4097403
S14: =Pivot_Source!L17 -> Snacks | T14: =Pivot_Source!M17 -> 8469.8915 | U14: =Pivot_Source!N17 -> 0.42026648
S15: =Pivot_Source!L18 -> Grocery | T15: =Pivot_Source!M18 -> 5921.1301 | U15: =Pivot_Source!N18 -> 0.29265353
S16: =Pivot_Source!L19 -> Bakery | T16: =Pivot_Source!M19 -> 5486.6339 | U16: =Pivot_Source!N19 -> 0.41495514
S17: =Pivot_Source!L20 -> Dairy | T17: =Pivot_Source!M20 -> 5043.8795 | U17: =Pivot_Source!N20 -> 0.33454843
S18: =Pivot_Source!L21 -> Grand Total | T18: =Pivot_Source!M21 -> 38138.273 | U18: =Pivot_Source!N21 -> 0.37782561
S19: =Pivot_Source!L22 -> 0 | T19: =Pivot_Source!M22 -> 0 | U19: =Pivot_Source!N22 -> 0
S26: Category | T26: Gross profit | U26: Gross Margin %
S27: =Pivot_Source!P16 -> Grocery | T27: =Pivot_Source!Q16 -> 5921.1301 | U27: =Pivot_Source!R16 -> 0.29265353
S28: =Pivot_Source!P17 -> Dairy | T28: =Pivot_Source!Q17 -> 5043.8795 | U28: =Pivot_Source!R17 -> 0.33454843
S29: =Pivot_Source!P18 -> Beverages | T29: =Pivot_Source!Q18 -> 13216.738 | U29: =Pivot_Source!R18 -> 0.4097403
S30: =Pivot_Source!P19 -> Bakery | T30: =Pivot_Source!Q19 -> 5486.6339 | U30: =Pivot_Source!R19 -> 0.41495514
S31: =Pivot_Source!P20 -> Snacks | T31: =Pivot_Source!Q20 -> 8469.8915 | U31: =Pivot_Source!R20 -> 0.42026648
S32: =Pivot_Source!P21 -> Grand Total | T32: =Pivot_Source!Q21 -> 38138.273 | U32: =Pivot_Source!R21 -> 0.37782561

Sheet Risk Table Source
B2: Inventory Risk Table | Source Data
B4: Power Query Output for Low Stock and Out of Stock Items
B7: ProductCategory | C7: ProductName | D7: ReorderLevel | E7: CurrentStockQty | F7: VarianceVsReorder | G7: CurrentStockValue | H7: Status
B8: Canned | C8: Chickpeas 500g | D8: 38 | E8: -53 | F8: -91 | G8: -126.14 | H8: Out of Stock
B9: Frozen | C9: Frozen Pizza 350g | D9: 27 | E9: 27 | F9: 0 | G9: 121.5 | H9: Low Stock

Sheet Products
A1: ProductID | B1: ProductName | C1: Category | D1: Brand | E1: Unit | F1: UnitPrice | G1: CostPrice | H1: ReorderLevel
A2: P0001 | B2: Green Tea 330ml | C2: Beverages | D2: FreshUp | E2: Can | F2: 3.39 | G2: 1.64 | H2: 33
A3: P0002 | B3: Green Tea 500ml | C3: Beverages | D3: SunDrop | E3: Bottle | F3: 1.77 | G3: 1.11 | H3: 55
A4: P0003 | B4: Green Tea 1L | C4: Beverages | D4: AquaLife | E4: Bottle | F4: 2.55 | G4: 1.24 | H4: 32
A5: P0004 | B5: Black Tea 330ml | C5: Beverages | D5: VitaSip | E5: Bottle | F5: 2.87 | G5: 1.39 | H5: 52
A6: P0005 | B6: Black Tea 500ml | C6: Beverages | D6: FreshUp | E6: Can | F6: 2.54 | G6: 1.45 | H6: 18
A7: P0006 | B7: Black Tea 1L | C7: Beverages | D7: SunDrop | E7: Can | F7: 3.86 | G7: 1.98 | H7: 39
A8: P0007 | B8: Orange Juice 330ml | C8: Beverages | D8: AquaLife | E8: Can | F8: 1.98 | G8: 1.04 | H8: 24
A9: P0008 | B9: Orange Juice 1L | C9: Beverages | D9: VitaSip | E9: Can | F9: 1.26 | G9: 0.63 | H9: 34
A10: P0009 | B10: Apple Juice 330ml | C10: Beverages | D10: FreshUp | E10: Bottle | F10: 4.05 | G10: 2.54 | H10: 42
A11: P0010 | B11: Apple Juice 1L | C11: Beverages | D11: SunDrop | E11: Can | F11: 1.21 | G11: 0.65 | H11: 54
A12: P0011 | B12: Sparkling Water 500ml | C12: Beverages | D12: AquaLife | E12: Bottle | F12: 1.65 | G12: 0.81 | H12: 36
A13: P0012 | B13: Sparkling Water 1L | C13: Beverages | D13: VitaSip | E13: Bottle | F13: 4.74 | G13: 3.09 | H13: 42
... A221: P0220 | B221: Laundry Gel 1L | C221: Cleaning | D221: EcoWash | E221: Bottle | F221: 5.34 | G221: 3.35 | H221: 28

Sheet Customers
A1: CustomerID | B1: CustomerName | C1: Region | D1: City | E1: Segment | F1: Phone | G1: Email
A2: C0001 | B2: Barda Partners LLC | C2: Aran | D2: Barda | E2: Corporate | F2: +(99470) 419-7911 | G2: barda-partners-llc@example.az
A3: C0002 | B3: Sharur Grocery Center 002 | C3: Nakhchivan | D3: Sharur | E3: Wholesale | F3: +(99477) 548-2413 | G3: sharur-grocery-center-002@example.az
A4: C0003 | B4: Qusar Wholesale LLC 003 | C4: Guba-Khachmaz | D4: Qusar | E4: Wholesale | F4: +(99477) 912-5900 | G4: qusar-wholesale-llc-003@example.az
A5: C0004 | B5: Naftalan Mini Market Plus 004 | C5: Ganja-Dashkasan | D5: Naftalan | E5: Corporate | F5: +(99477) 742-5184 | G5: naftalan-mini-market-plus-004@example.az
A6: C0005 | B6: Sumqayit Partners Hub | C6: Absheron | D6: Sumqayit | E6: Retail | F6: +(99470) 162-1086 | G6: sumqayit-partners-hub@example.az
A7: C0006 | B7: Khirdalan Retail Center 006 | C7: Absheron | D7: Khirdalan | E7: Retail | F7: +(99450) 341-8526 | G7: khirdalan-retail-center-006@example.az
A8: C0007 | B8: Zagatala Retail Hub 007 | C8: Shaki-Zagatala | D8: Zagatala | E8: Retail | F8: +(99450) 651-2415 | G8: zagatala-retail-hub-007@example.az
A9: C0008 | B9: Shabran Trade House Plus 008 | C9: Guba-Khachmaz | D9: Shabran | E9: HoReCa | F9: +(99451) 582-1419 | G9: shabran-trade-house-plus-008@example.az
A10: C0009 | B10: Shusha Retail Hub | C10: Karabakh-East Zangezur | D10: Shusha | E10: Retail | F10: +(99455) 148-5654 | G10: shusha-retail-hub@example.az
A11: C0010 | B11: Baku Foods Center 010 | C11: Absheron | D11: Baku | E11: Retail | F11: +(99470) 402-0853 | G11: baku-foods-center-010@example.az
A12: C0011 | B12: Baku Wholesale Group 011 | C12: Absheron | D12: Baku | E12: Wholesale | F12: +(99451) 489-5475 | G12: baku-wholesale-group-011@example.az
... A751: C0750 | B751: Barda Foods Center 750 | C751: Aran | D751: Barda | E751: Wholesale | F751: +994708679146 | G751: barda-foods-center-750@example.az

Sheet Sales
A1: SaleID | B1: Date | C1: CustomerID | D1: ProductID | E1: Quantity | F1: UnitPrice | G1: Discount | H1: TotalAmount | I1: Salesperson | J1: ProductCategory | K1: CustomerRegion
A2: S00001 | B2: 45658 | C2: C0078 | D2: P0036 | E2: 13 | F2: =IFERROR(VLOOKUP(D2,Products!$A$2:$H$221,6,FALSE),0) -> 1.36 | G2: 0.03 | H2: =ROUND(E2*F2*(1-G2),2) -> 17.15 | I2: Aysel | J2: =IFERROR(VLOOKUP(D2,Products!$A$2:$H$221,3,FALSE),"") -> Snacks | K2: =IFERROR(VLOOKUP(C2,Customers!$A$2:$G$751,3,FALSE),"") -> Guba-Khachmaz
A3: S00002 | B3: 45658 | C3: C0108 | D3: P0053 | E3: 14 | F3: =IFERROR(VLOOKUP(D3,Products!$A$2:$H$221,6,FALSE),0) -> 3.47 | G3: 0.12 | H3: =ROUND(E3*F3*(1-G3),2) -> 42.75 | I3: Rauf | J3: =IFERROR(VLOOKUP(D3,Products!$A$2:$H$221,3,FALSE),"") -> Dairy | K3: =IFERROR(VLOOKUP(C3,Customers!$A$2:$G$751,3,FALSE),"") -> Lankaran-Astara
A4: S00003 | B4: 45658 | C4: C0108 | D4: P0211 | E4: 8 | F4: =IFERROR(VLOOKUP(D4,Products!$A$2:$H$221,6,FALSE),0) -> 6.47 | G4: 0.03 | H4: =ROUND(E4*F4*(1-G4),2) -> 50.21 | I4: Rauf | J4: =IFERROR(VLOOKUP(D4,Products!$A$2:$H$221,3,FALSE),"") -> Cleaning | K4: =IFERROR(VLOOKUP(C4,Customers!$A$2:$G$751,3,FALSE),"") -> Lankaran-Astara
A5: S00004 | B5: 45658 | C5: C0129 | D5: P0113 | E5: 5 | F5: =IFERROR(VLOOKUP(D5,Products!$A$2:$H$221,6,FALSE),0) -> 1.21 | G5: 0 | H5: =ROUND(E5*F5*(1-G5),2) -> 6.05 | I5: Aysel | J5: =IFERROR(VLOOKUP(D5,Products!$A$2:$H$221,3,FALSE),"") -> Household | K5: =IFERROR(VLOOKUP(C5,Customers!$A$2:$G$751,3,FALSE),"") -> Nakhchivan
A6: S00005 | B6: 45658 | C6: C0233 | D6: P0066 | E6: 7 | F6: =IFERROR(VLOOKUP(D6,Products!$A$2:$H$221,6,FALSE),0) -> 5.52 | G6: 0 | H6: =ROUND(E6*F6*(1-G6),2) -> 38.64 | I6: Sabina | J6: =IFERROR(VLOOKUP(D6,Products!$A$2:$H$221,3,FALSE),"") -> Dairy | K6: =IFERROR(VLOOKUP(C6,Customers!$A$2:$G$751,3,FALSE),"") -> Absheron
A7: S00006 | B7: 45658 | C7: C0382 | D7: P0104 | E7: 14 | F7: =IFERROR(VLOOKUP(D7,Products!$A$2:$H$221,6,FALSE),0) -> 3.46 | G7: 0.07 | H7: =ROUND(E7*F7*(1-G7),2) -> 45.05 | I7: Rauf | J7: =IFERROR(VLOOKUP(D7,Products!$A$2:$H$221,3,FALSE),"") -> Grocery | K7: =IFERROR(VLOOKUP(C7,Customers!$A$2:$G$751,3,FALSE),"") -> Karabakh-East Zangezur
A8: S00007 | B8: 45658 | C8: C0461 | D8: P0175 | E8: 2 | F8: =IFERROR(VLOOKUP(D8,Products!$A$2:$H$221,6,FALSE),0) -> 8.06 | G8: 0.15 | H8: =ROUND(E8*F8*(1-G8),2) -> 13.7 | I8: Murad | J8: =IFERROR(VLOOKUP(D8,Products!$A$2:$H$221,3,FALSE),"") -> Frozen | K8: =IFERROR(VLOOKUP(C8,Customers!$A$2:$G$751,3,FALSE),"") -> Absheron
A9: S00008 | B9: 45658 | C9: C0493 | D9: P0012 | E9: 27 | F9: =IFERROR(VLOOKUP(D9,Products!$A$2:$H$221,6,FALSE),0) -> 4.74 | G9: 0.05 | H9: =ROUND(E9*F9*(1-G9),2) -> 121.58 | I9: Aysel | J9: =IFERROR(VLOOKUP(D9,Products!$A$2:$H$221,3,FALSE),"") -> Beverages | K9: =IFERROR(VLOOKUP(C9,Customers!$A$2:$G$751,3,FALSE),"") -> Guba-Khachmaz
A10: S00009 | B10: 45658 | C10: C0571 | D10: P0119 | E10: 9 | F10: =IFERROR(VLOOKUP(D10,Products!$A$2:$H$221,6,FALSE),0) -> 1.23 | G10: 0.1 | H10: =ROUND(E10*F10*(1-G10),2) -> 9.96 | I10: Nigar | J10: =IFERROR(VLOOKUP(D10,Products!$A$2:$H$221,3,FALSE),"") -> Household | K10: =IFERROR(VLOOKUP(C10,Customers!$A$2:$G$751,3,FALSE),"") -> Shaki-Zagatala
A11: S00010 | B11: 45658 | C11: C0626 | D11: P0030 | E11: 18 | F11: =IFERROR(VLOOKUP(D11,Products!$A$2:$H$221,6,FALSE),0) -> 4 | G11: 0 | H11: =ROUND(E11*F11*(1-G11),2) -> 72 | I11: Aysel | J11: =IFERROR(VLOOKUP(D11,Products!$A$2:$H$221,3,FALSE),"") -> Snacks | K11: =IFERROR(VLOOKUP(C11,Customers!$A$2:$G$751,3,FALSE),"") -> Lankaran-Astara
A12: S00011 | B12: 45658 | C12: C0645 | D12: P0113 | E12: 14 | F12: =IFERROR(VLOOKUP(D12,Products!$A$2:$H$221,6,FALSE),0) -> 1.21 | G12: 0 | H12: =ROUND(E12*F12*(1-G12),2) -> 16.94 | I12: Rauf | J12: =IFERROR(VLOOKUP(D12,Products!$A$2:$H$221,3,FALSE),"") -> Household | K12: =IFERROR(VLOOKUP(C12,Customers!$A$2:$G$751,3,FALSE),"") -> Karabakh-East Zangezur
A13: S00012 | B13: 45658 | C13: C0685 | D13: P0018 | E13: 29 | F13: =IFERROR(VLOOKUP(D13,Products!$A$2:$H$221,6,FALSE),0) -> 4.04 | G13: 0.03 | H13: =ROUND(E13*F13*(1-G13),2) -> 113.65 | I13: Nigar | J13: =IFERROR(VLOOKUP(D13,Products!$A$2:$H$221,3,FALSE),"") -> Beverages | K13: =IFERROR(VLOOKUP(C13,Customers!$A$2:$G$751,3,FALSE),"") -> Ganja-Dashkasan
... A4501: S04500 | B4501: 46022 | C4501: C0680 | D4501: P0013 | E4501: 29 | F4501: =IFERROR(VLOOKUP(D4501,Products!$A$2:$H$221,6,FALSE),0) -> 1.98 | G4501: 0.12 | H4501: =ROUND(E4501*F4501*(1-G4501),2) -> 50.53 | I4501: Elvin | J4501: =IFERROR(VLOOKUP(D4501,Products!$A$2:$H$221,3,FALSE),"") -> Beverages | K4501: =IFERROR(VLOOKUP(C4501,Customers!$A$2:$G$751,3,FALSE),"") -> Guba-Khachmaz

Sheet Inventory_Movements
A1: MovementID | B1: Date | C1: ProductID | D1: MovementType (IN/OUT) | E1: Quantity | F1: Warehouse | G1: Supplier
A2: M00001 | B2: 45658 | C2: P0037 | D2: IN | E2: 58 | F2: Baku WH | G2: South Agro
A3: M00002 | B3: 45658 | C3: P0040 | D3: IN | E3: 131 | F3: Baku WH | G3: Atlas Import
A4: M00003 | B4: 45658 | C4: P0073 | D4: IN | E4: 78 | F4: Baku WH | G4: Atlas Import
A5: M00004 | B5: 45658 | C5: P0084 | D5: IN | E5: 110 | F5: Lankaran WH | G5: Prime Distribution
A6: M00005 | B6: 45658 | C6: P0085 | D6: IN | E6: 55 | F6: Baku WH | G6: Atlas Import
A7: M00006 | B7: 45658 | C7: P0088 | D7: OUT | E7: 7 | F7: Baku WH | G7: Unknown Supplier
A8: M00007 | B8: 45658 | C8: P0105 | D8: IN | E8: 62 | F8: Baku WH | G8: West Supply
A9: M00008 | B9: 45658 | C9: P0128 | D9: IN | E9: 99 | F9: Ganja WH | G9: West Supply
A10: M00009 | B10: 45658 | C10: P0135 | D10: OUT | E10: 11 | F10: Ganja WH | G10: Unknown Supplier
A11: M00010 | B11: 45659 | C11: P0006 | D11: IN | E11: 131 | F11: Baku WH | G11: FreshRoute
A12: M00011 | B12: 45659 | C12: P0017 | D12: IN | E12: 62 | F12: Baku WH | G12: South Agro
A13: M00012 | B13: 45659 | C13: P0042 | D13: OUT | E13: 21 | F13: Nakhchivan WH | G13: Unknown Supplier
... A3201: M03200 | B3201: 46022 | C3201: P0176 | D3201: IN | E3201: 29 | F3201: Lankaran WH | G3201: FreshRoute

Sheet Calendar
A1: Date | B1: Year | C1: Month | D1: MonthName | E1: Quarter | F1: Weekday | G1: WeekdayName
A2: 45658 | B2: =YEAR(A2) -> 2025 | C2: =MONTH(A2) -> 1 | D2: =TEXT(A2,"mmmm") -> January | E2: =ROUNDUP(MONTH(A2)/3,0) -> 1 | F2: =WEEKDAY(A2,2) -> 3 | G2: =TEXT(A2,"dddd") -> Wednesday
A3: 45659 | B3: =YEAR(A3) -> 2025 | C3: =MONTH(A3) -> 1 | D3: =TEXT(A3,"mmmm") -> January | E3: =ROUNDUP(MONTH(A3)/3,0) -> 1 | F3: =WEEKDAY(A3,2) -> 4 | G3: =TEXT(A3,"dddd") -> Thursday
A4: 45660 | B4: =YEAR(A4) -> 2025 | C4: =MONTH(A4) -> 1 | D4: =TEXT(A4,"mmmm") -> January | E4: =ROUNDUP(MONTH(A4)/3,0) -> 1 | F4: =WEEKDAY(A4,2) -> 5 | G4: =TEXT(A4,"dddd") -> Friday
A5: 45661 | B5: =YEAR(A5) -> 2025 | C5: =MONTH(A5) -> 1 | D5: =TEXT(A5,"mmmm") -> January | E5: =ROUNDUP(MONTH(A5)/3,0) -> 1 | F5: =WEEKDAY(A5,2) -> 6 | G5: =TEXT(A5,"dddd") -> Saturday
A6: 45662 | B6: =YEAR(A6) -> 2025 | C6: =MONTH(A6) -> 1 | D6: =TEXT(A6,"mmmm") -> January | E6: =ROUNDUP(MONTH(A6)/3,0) -> 1 | F6: =WEEKDAY(A6,2) -> 7 | G6: =TEXT(A6,"dddd") -> Sunday
A7: 45663 | B7: =YEAR(A7) -> 2025 | C7: =MONTH(A7) -> 1 | D7: =TEXT(A7,"mmmm") -> January | E7: =ROUNDUP(MONTH(A7)/3,0) -> 1 | F7: =WEEKDAY(A7,2) -> 1 | G7: =TEXT(A7,"dddd") -> Monday
A8: 45664 | B8: =YEAR(A8) -> 2025 | C8: =MONTH(A8) -> 1 | D8: =TEXT(A8,"mmmm") -> January | E8: =ROUNDUP(MONTH(A8)/3,0) -> 1 | F8: =WEEKDAY(A8,2) -> 2 | G8: =TEXT(A8,"dddd") -> Tuesday
A9: 45665 | B9: =YEAR(A9) -> 2025 | C9: =MONTH(A9) -> 1 | D9: =TEXT(A9,"mmmm") -> January | E9: =ROUNDUP(MONTH(A9)/3,0) -> 1 | F9: =WEEKDAY(A9,2) -> 3 | G9: =TEXT(A9,"dddd") -> Wednesday
A10: 45666 | B10: =YEAR(A10) -> 2025 | C10: =MONTH(A10) -> 1 | D10: =TEXT(A10,"mmmm") -> January | E10: =ROUNDUP(MONTH(A10)/3,0) -> 1 | F10: =WEEKDAY(A10,2) -> 4 | G10: =TEXT(A10,"dddd") -> Thursday
A11: 45667 | B11: =YEAR(A11) -> 2025 | C11: =MONTH(A11) -> 1 | D11: =TEXT(A11,"mmmm") -> January | E11: =ROUNDUP(MONTH(A11)/3,0) -> 1 | F11: =WEEKDAY(A11,2) -> 5 | G11: =TEXT(A11,"dddd") -> Friday
A12: 45668 | B12: =YEAR(A12) -> 2025 | C12: =MONTH(A12) -> 1 | D12: =TEXT(A12,"mmmm") -> January | E12: =ROUNDUP(MONTH(A12)/3,0) -> 1 | F12: =WEEKDAY(A12,2) -> 6 | G12: =TEXT(A12,"dddd") -> Saturday
A13: 45669 | B13: =YEAR(A13) -> 2025 | C13: =MONTH(A13) -> 1 | D13: =TEXT(A13,"mmmm") -> January | E13: =ROUNDUP(MONTH(A13)/3,0) -> 1 | F13: =WEEKDAY(A13,2) -> 7 | G13: =TEXT(A13,"dddd") -> Sunday
... A366: 46022 | B366: =YEAR(A366) -> 2025 | C366: =MONTH(A366) -> 12 | D366: =TEXT(A366,"mmmm") -> December | E366: =ROUNDUP(MONTH(A366)/3,0) -> 4 | F366: =WEEKDAY(A366,2) -> 3 | G366: =TEXT(A366,"dddd") -> Wednesday

Sheet Pivot_Source
Q1: Last Updated: | R1: =TODAY() -> 46134
B2: november | C2: Net Sales | E2: Row Labels | F2: Net Sales | H2: Row Labels | I2: Stock In Qty | J2: Stock Out Qty | K2: Current Stock Qty | L2: Current Stock Value | M2: Low Stock Products | N2: Out of Stock Products
B3: January | C3: 14305.456 | E3: Shaki-Zagatala | F3: 15542.516 | H3: Bakery | I3: 16611 | J3: 3299 | K3: 13312 | L3: 12334.3
B4: February | C4: 11030.163 | E4: Absheron | F4: 48856.082 | H4: Beverages | I4: 32117 | J4: 4316 | K4: 27801 | L4: 43568
B5: March | C5: 13640.536 | E5: Aran | F5: 21384.483 | H5: Canned | I5: 6953 | J5: 1002 | K5: 5951 | L5: 15447.76 | N5: 1
B6: April | C6: 12448.502 | E6: Ganja-Dashkasan | F6: 16151.497 | H6: Cleaning | I6: 6697 | J6: 522 | K6: 6175 | L6: 19837.99
B7: May | C7: 12486.382 | E7: Guba-Khachmaz | F7: 17675.947 | H7: Dairy | I7: 11651 | J7: 1578 | K7: 10073 | L7: 20704.07
B8: June | C8: 12753.028 | E8: Karabakh-East Zangezur | F8: 9579.1866 | H8: Frozen | I8: 5584 | J8: 497 | K8: 5087 | L8: 19411.09 | M8: 1
B9: July | C9: 11793.649 | E9: Lankaran-Astara | F9: 13977.534 | H9: Grocery | I9: 13007 | J9: 1626 | K9: 11381 | L9: 34471.99
B10: August | C10: 12880.036 | E10: Nakhchivan | F10: 6066.9651 | H10: Household | I10: 11748 | J10: 1222 | K10: 10526 | L10: 15959.2
B11: September | C11: 11616.129 | E11: Grand Total | F11: 149234.21 | H11: Personal Care | I11: 6808 | J11: 657 | K11: 6151 | L11: 14749.8
B12: October | C12: 11456.97 | H12: Snacks | I12: 20127 | J12: 3166 | K12: 16961 | L12: 27469.31
B13: November | C13: 11869.544 | E13: Row Labels | F13: Net Sales | H13: Grand Total | I13: 131303 | J13: 17885 | K13: 113418 | L13: 223953.51 | M13: 1 | N13: 1
B14: December | C14: 12953.817 | E14: Leyla | F14: 16744.196
B15: Grand Total | C15: 149234.21 | E15: Elvin | F15: 17368.824 | H15: Row Labels | I15: Stock In Qty | J15: Stock Out Qty | L15: Row Labels | M15: Gross Profit | N15: Gross Margin % | P15: Row Labels | Q15: Gross Profit | R15: Gross Margin %
E16: Sabina | F16: 17567.313 | H16: Frozen | I16: 5584 | J16: 497 | L16: Beverages | M16: 13216.738 | N16: 0.4097403 | P16: Grocery | Q16: 5921.1301 | R16: 0.29265353
B17: Row Labels | C17: Net Sales | E17: Nigar | F17: 18460.362 | H17: Cleaning | I17: 6697 | J17: 522 | L17: Snacks | M17: 8469.8915 | N17: 0.42026648 | P17: Dairy | Q17: 5043.8795 | R17: 0.33454843
B18: Household | C18: 7876.0985 | E18: Murad | F18: 19266.412 | H18: Personal Care | I18: 6808 | J18: 657 | L18: Grocery | M18: 5921.1301 | N18: 0.29265353 | P18: Beverages | Q18: 13216.738 | R18: 0.4097403
B19: Cleaning | C19: 8330.9465 | E19: Kamran | F19: 19611.072 | H19: Canned | I19: 6953 | J19: 1002 | L19: Bakery | M19: 5486.6339 | N19: 0.41495514 | P19: Bakery | Q19: 5486.6339 | R19: 0.41495514
B20: Personal Care | C20: 9052.8248 | E20: Aysel | F20: 20065.858 | H20: Dairy | I20: 11651 | J20: 1578 | L20: Dairy | M20: 5043.8795 | N20: 0.33454843 | P20: Snacks | Q20: 8469.8915 | R20: 0.42026648
B21: Frozen | C21: 11225.692 | E21: Rauf | F21: 20150.175 | H21: Household | I21: 11748 | J21: 1222 | L21: Grand Total | M21: 38138.273 | N21: 0.37782561 | P21: Grand Total | Q21: 38138.273 | R21: 0.37782561
B22: Canned | C22: 11807.175 | E22: Grand Total | F22: 149234.21 | H22: Grocery | I22: 13007 | J22: 1626
B23: Bakery | C23: 13222.234 | H23: Bakery | I23: 16611 | J23: 3299
B24: Dairy | C24: 15076.679 | E24: Step | F24: Value | H24: Snacks | I24: 20127 | J24: 3166
B25: Snacks | C25: 20153.621 | E25: Gross Sales | F25: =GETPIVOTDATA("[Measures].[Gross Sales]",KPISheet!$B$3) -> 157289.34 | H25: Beverages | I25: 32117 | J25: 4316
B26: Grocery | C26: 20232.56 | E26: Discount Amount | F26: =GETPIVOTDATA("[Measures].[Discount Amount]",KPISheet!$B$3)*(-1) -> -8055.1296 | H26: Grand Total | I26: 131303 | J26: 17885 | M26: Row Labels
B27: Beverages | C27: 32256.378 | E27: Net Sales | F27: =GETPIVOTDATA("[Measures].[Net Sales]",KPISheet!$B$3) -> 149234.21 | M27: January
B28: Grand Total | C28: 149234.21 | E28: COGS | F28: =GETPIVOTDATA("[Measures].[COGS]",KPISheet!$B$3)*(-1) -> -92961.54 | M28: February
E29: Gross Profi | F29: =GETPIVOTDATA("[Measures].[Gross Profit]",KPISheet!$B$3) -> 56272.67 | M29: March
B30: Row Labels | C30: Current Stock Value | M30: April
B31: Bakery | C31: 12334.3 | E31: Gross Profit | F31: Column Labels | M31: May
B32: Personal Care | C32: 14749.8 | E32: Row Labels | F32: Corporate | G32: Distributor | H32: HoReCa | I32: Retail | J32: Wholesale | K32: Grand Total | M32: June
B33: Canned | C33: 15447.76 | E33: Absheron | F33: 1551.8699 | G33: 1968.1459 | H33: 420.8722 | I33: 10079.843 | J33: 4599.0112 | K33: 18619.742 | M33: July
B34: Household | C34: 15959.2 | E34: Aran | F34: 520.495 | G34: 1220.4913 | H34: 182.8937 | I34: 4007.5241 | J34: 2175.7191 | K34: 8107.1232 | M34: August
B35: Frozen | C35: 19411.09 | E35: Ganja-Dashkasan | F35: 465.2833 | G35: 1036.2002 | H35: 107.081 | I35: 2915.7889 | J35: 1655.7335 | K35: 6180.0869 | M35: September
B36: Cleaning | C36: 19837.99 | E36: Guba-Khachmaz | F36: 491.9771 | G36: 922.2586 | H36: 447.5248 | I36: 3415.5905 | J36: 1278.3757 | K36: 6555.7267 | M36: October
B37: Dairy | C37: 20704.07 | E37: Karabakh-East Zangezur | F37: 445.1423 | G37: 571.8545 | H37: 81.0547 | I37: 1754.2701 | J37: 741.165 | K37: 3593.4866 | M37: November
B38: Snacks | C38: 27469.31 | E38: Lankaran-Astara | F38: 347.4963 | G38: 660.529 | H38: 80.4299 | I38: 2659.6225 | J38: 1416.2063 | K38: 5164.284 | M38: December
B39: Grocery | C39: 34471.99 | E39: Nakhchivan | F39: 172.7443 | G39: 431.089 | H39: 16.8022 | I39: 929.5029 | J39: 696.0467 | K39: 2246.1851 | M39: Grand Total
B40: Beverages | C40: 43568 | E40: Shaki-Zagatala | F40: 510.4476 | G40: 511.6981 | H40: 261.1244 | I40: 3157.5019 | J40: 1365.264 | K40: 5806.036
...

Sheet KPISheet
D1: =B4 -> Net Sales | E1: =B5 -> Gross Profit | F1: =B6 -> Gross Margin % | G1: =B7 -> Order Count | H1: =B8 -> Unique Customers | I1: =B9 -> Average Order Value | J1: =B10 -> Current Stock Value | K1: =B11 -> Low Stock Products | L1: =B12 -> Out of Stock Products | M1: =B13 -> MTD Sales | N1: =B14 -> YTD Sales | O1: =B15 -> Discount Rate % | Q1: Current Stock Qty | R1: Stock In Qty | S1: Stock Out Qty | T1: Gross Sales | U1: Discount Amount | V1: COGS | W1: Inventory Net Movement | X1: Low Stock Value | Y1: Active Products | Z1: Active Salespersons | AA1: Average Discount per Order | AB1: Margin Value per Customer | AC1: Profit per Order | AD1: MTD Gross Profit | AE1: Total Risk Products | AF1: Net Sales Check | AG1: Net Sales Variance | AH1: Total Qty | AI1: Average Selling Price | AJ1: Product Count Sold | AK1: Sales per Customer | AL1: Qty per Order | AM1: Previous Month Sales | AN1: MoM Growth | AO1: MoM Growth % | AP1: YTD Gross Profit | AQ1: Previous Year Sales | AR1: YoY Growth | AS1: YoY Growth %
D2: =GETPIVOTDATA("[Measures].[Net Sales]",$B$3) -> 149234.21 | E2: =GETPIVOTDATA("[Measures].[Gross Profit]",$B$3) -> 56272.67 | F2: =GETPIVOTDATA("[Measures].[Gross Margin %]",$B$3) -> 0.37707621 | G2: =GETPIVOTDATA("[Measures].[Order Count]",$B$3) -> 4500 | H2: =GETPIVOTDATA("[Measures].[Unique Customers]",$B$3) -> 747 | I2: =GETPIVOTDATA("[Measures].[Average Order Value]",$B$3) -> 33.163158 | J2: =GETPIVOTDATA("[Measures].[Current Stock Value]",$B$3) -> 223953.51 | K2: =GETPIVOTDATA("[Measures].[Low Stock Products]",$B$3) -> 1 | L2: =GETPIVOTDATA("[Measures].[Out of Stock Products]",$B$3) -> 1 | M2: =GETPIVOTDATA("[Measures].[MTD Sales]",$B$3) -> 12953.817 | N2: =GETPIVOTDATA("[Measures].[MTD Sales]",$B$3) -> 12953.817 | O2: =GETPIVOTDATA("[Measures].[Discount Rate %]",$B$3) -> 0.051212178 | Q2: 113418 | R2: 131303 | S2: 17885 | T2: 157289.34 | U2: 8055.1296 | V2: 92961.54 | W2: 113418 | X2: 121.5 | Y2: 220 | Z2: 8 | AA2: 1.7900288 | AB2: 75.331553 | AC2: 12.505038 | AD2: 4806.8966 | AE2: 2 | AF2: 149235.06 | AG2: -0.8496 | AH2: 48676 | AI2: 3.0658684 | AJ2: 220 | AK2: 199.77806 | AL2: 10.816889 | AM2: 136280.39 | AN2: 12953.817 | AO2: 0.09505268 | AP2: 56272.67
B3: Values
B4: Net Sales | C4: 149234.21
B5: Gross Profit | C5: 56272.67
B6: Gross Margin % | C6: 0.37707621
B7: Order Count | C7: 4500
B8: Unique Customers | C8: 747
B9: Average Order Value | C9: 33.163158
B10: Current Stock Value | C10: 223953.51
B11: Low Stock Products | C11: 1
B12: Out of Stock Products | C12: 1
B13: MTD Sales | C13: 12953.817
B14: YTD Sales | C14: 149234.21
B15: Discount Rate % | C15: 0.051212178
... B41: YTD Gross Profit | C41: 56272.67
B42: Previous Year Sales
B43: YoY Growth
B44: YoY Growth %
